[2021-02-13 15:16:17] - ERROR    - Internal Server Error: /accounts/login/
Traceback (most recent call last):
  File "C:\Users\youssri.ahmed.CONTACTGROUP\.conda\envs\omflow\lib\site-packages\django\template\backends\django.py", line 61, in render
    return self.template.render(context)
  File "C:\Users\youssri.ahmed.CONTACTGROUP\.conda\envs\omflow\lib\site-packages\django\template\base.py", line 170, in render
    return self._render(context)
  File "C:\Users\youssri.ahmed.CONTACTGROUP\.conda\envs\omflow\lib\site-packages\django\template\base.py", line 162, in _render
    return self.nodelist.render(context)
  File "C:\Users\youssri.ahmed.CONTACTGROUP\.conda\envs\omflow\lib\site-packages\django\template\base.py", line 938, in render
    bit = node.render_annotated(context)
  File "C:\Users\youssri.ahmed.CONTACTGROUP\.conda\envs\omflow\lib\site-packages\django\template\base.py", line 905, in render_annotated
    return self.render(context)
  File "C:\Users\youssri.ahmed.CONTACTGROUP\.conda\envs\omflow\lib\site-packages\django\template\loader_tags.py", line 150, in render
    return compiled_parent._render(context)
  File "C:\Users\youssri.ahmed.CONTACTGROUP\.conda\envs\omflow\lib\site-packages\django\template\base.py", line 162, in _render
    return self.nodelist.render(context)
  File "C:\Users\youssri.ahmed.CONTACTGROUP\.conda\envs\omflow\lib\site-packages\django\template\base.py", line 938, in render
    bit = node.render_annotated(context)
  File "C:\Users\youssri.ahmed.CONTACTGROUP\.conda\envs\omflow\lib\site-packages\django\template\base.py", line 905, in render_annotated
    return self.render(context)
  File "C:\Users\youssri.ahmed.CONTACTGROUP\.conda\envs\omflow\lib\site-packages\django\template\loader_tags.py", line 180, in render
    template = context.template.engine.select_template(template_name)
  File "C:\Users\youssri.ahmed.CONTACTGROUP\.conda\envs\omflow\lib\site-packages\django\template\engine.py", line 180, in select_template
    raise TemplateDoesNotExist(', '.join(not_found))
django.template.exceptions.TemplateDoesNotExist: base_import.html

The above exception was the direct cause of the following exception:

Traceback (most recent call last):
  File "C:\Users\youssri.ahmed.CONTACTGROUP\.conda\envs\omflow\lib\site-packages\django\core\handlers\exception.py", line 47, in inner
    response = get_response(request)
  File "C:\Users\youssri.ahmed.CONTACTGROUP\.conda\envs\omflow\lib\site-packages\django\core\handlers\base.py", line 181, in _get_response
    response = wrapped_callback(request, *callback_args, **callback_kwargs)
  File "E:\programing\python\qhse-erp\home\aeraeg\python\apps\omflow\omuser\views.py", line 43, in loginPage
    return render(request, "login.html")
  File "C:\Users\youssri.ahmed.CONTACTGROUP\.conda\envs\omflow\lib\site-packages\django\shortcuts.py", line 19, in render
    content = loader.render_to_string(template_name, context, request, using=using)
  File "C:\Users\youssri.ahmed.CONTACTGROUP\.conda\envs\omflow\lib\site-packages\django\template\loader.py", line 62, in render_to_string
    return template.render(context, request)
  File "C:\Users\youssri.ahmed.CONTACTGROUP\.conda\envs\omflow\lib\site-packages\django\template\backends\django.py", line 63, in render
    reraise(exc, self.backend)
  File "C:\Users\youssri.ahmed.CONTACTGROUP\.conda\envs\omflow\lib\site-packages\django\template\backends\django.py", line 84, in reraise
    raise new from exc
django.template.exceptions.TemplateDoesNotExist: base_import.html
[2021-02-13 15:16:20] - ERROR    - "GET /accounts/login/?next=/ HTTP/1.1" 500 135754
[2021-02-13 15:16:47] - ERROR    - Internal Server Error: /accounts/login/
Traceback (most recent call last):
  File "C:\Users\youssri.ahmed.CONTACTGROUP\.conda\envs\omflow\lib\site-packages\django\template\backends\django.py", line 61, in render
    return self.template.render(context)
  File "C:\Users\youssri.ahmed.CONTACTGROUP\.conda\envs\omflow\lib\site-packages\django\template\base.py", line 170, in render
    return self._render(context)
  File "C:\Users\youssri.ahmed.CONTACTGROUP\.conda\envs\omflow\lib\site-packages\django\template\base.py", line 162, in _render
    return self.nodelist.render(context)
  File "C:\Users\youssri.ahmed.CONTACTGROUP\.conda\envs\omflow\lib\site-packages\django\template\base.py", line 938, in render
    bit = node.render_annotated(context)
  File "C:\Users\youssri.ahmed.CONTACTGROUP\.conda\envs\omflow\lib\site-packages\django\template\base.py", line 905, in render_annotated
    return self.render(context)
  File "C:\Users\youssri.ahmed.CONTACTGROUP\.conda\envs\omflow\lib\site-packages\django\template\loader_tags.py", line 150, in render
    return compiled_parent._render(context)
  File "C:\Users\youssri.ahmed.CONTACTGROUP\.conda\envs\omflow\lib\site-packages\django\template\base.py", line 162, in _render
    return self.nodelist.render(context)
  File "C:\Users\youssri.ahmed.CONTACTGROUP\.conda\envs\omflow\lib\site-packages\django\template\base.py", line 938, in render
    bit = node.render_annotated(context)
  File "C:\Users\youssri.ahmed.CONTACTGROUP\.conda\envs\omflow\lib\site-packages\django\template\base.py", line 905, in render_annotated
    return self.render(context)
  File "C:\Users\youssri.ahmed.CONTACTGROUP\.conda\envs\omflow\lib\site-packages\django\template\loader_tags.py", line 180, in render
    template = context.template.engine.select_template(template_name)
  File "C:\Users\youssri.ahmed.CONTACTGROUP\.conda\envs\omflow\lib\site-packages\django\template\engine.py", line 180, in select_template
    raise TemplateDoesNotExist(', '.join(not_found))
django.template.exceptions.TemplateDoesNotExist: base_import.html

The above exception was the direct cause of the following exception:

Traceback (most recent call last):
  File "C:\Users\youssri.ahmed.CONTACTGROUP\.conda\envs\omflow\lib\site-packages\django\core\handlers\exception.py", line 47, in inner
    response = get_response(request)
  File "C:\Users\youssri.ahmed.CONTACTGROUP\.conda\envs\omflow\lib\site-packages\django\core\handlers\base.py", line 181, in _get_response
    response = wrapped_callback(request, *callback_args, **callback_kwargs)
  File "E:\programing\python\qhse-erp\home\aeraeg\python\apps\omflow\omuser\views.py", line 43, in loginPage
    return render(request, "login.html")
  File "C:\Users\youssri.ahmed.CONTACTGROUP\.conda\envs\omflow\lib\site-packages\django\shortcuts.py", line 19, in render
    content = loader.render_to_string(template_name, context, request, using=using)
  File "C:\Users\youssri.ahmed.CONTACTGROUP\.conda\envs\omflow\lib\site-packages\django\template\loader.py", line 62, in render_to_string
    return template.render(context, request)
  File "C:\Users\youssri.ahmed.CONTACTGROUP\.conda\envs\omflow\lib\site-packages\django\template\backends\django.py", line 63, in render
    reraise(exc, self.backend)
  File "C:\Users\youssri.ahmed.CONTACTGROUP\.conda\envs\omflow\lib\site-packages\django\template\backends\django.py", line 84, in reraise
    raise new from exc
django.template.exceptions.TemplateDoesNotExist: base_import.html
[2021-02-13 15:16:47] - ERROR    - "GET /accounts/login/?next=/ HTTP/1.1" 500 135754
